<?xml version="1.0" encoding="utf-8"?>
<robot  name="rightarm" xmlns:xacro="rosxacro">
  <link
    name="rightarm_link1">
    <inertial>
      <origin
        xyz="-5.55636001209336E-06 -0.028842621821945 -0.0719468523797095"
        rpy="0 0 0" />
      <mass
        value="0.185843840147316" />
      <inertia
        ixx="0.00064879513756714"
        ixy="2.97405201701726E-08"
        ixz="-2.74002482400952E-08"
        iyy="0.000733900314751328"
        iyz="0.000151109528398381"
        izz="0.000491282759255514" />
    </inertial>
    <visual>
      <origin
        xyz="0 0 0"
        rpy="0 0 0" />
      <geometry>
        <mesh
          filename="package://rightarm/meshes/rightarm_link1.STL" />
      </geometry>
      <material
        name="">
        <color
          rgba="0.898039215686275 0.913725490196078 0.925490196078431 1" />
      </material>
    </visual>
    <collision>
      <origin
        xyz="0 0 0"
        rpy="0 0 0" />
      <geometry>
        <mesh
          filename="package://rightarm/meshes/rightarm_link1.STL" />
      </geometry>
    </collision>
  </link>
  <joint
    name="rightarm_joint1"
    type="revolute">
    <origin
      xyz="0.252 0 0"
      rpy="1.5707963267949 -1.5707963267949 1.5707963267949" />
    <parent
      link="base_link" />
    <child
      link="rightarm_link1" />
    <axis
      xyz="0 0 1" />
    <limit
      lower="-2.9671"
      upper="2.9671"
      effort="100"
      velocity="5" />
  </joint>
  <link
    name="rightarm_link2">
    <inertial>
      <origin
        xyz="-8.00238164622158E-09 0.087181912478348 -0.000487247269088532"
        rpy="0 0 0" />
      <mass
        value="1.90490933692951" />
      <inertia
        ixx="0.0187743359656438"
        ixy="-1.72667652358285E-10"
        ixz="-2.36806138854804E-10"
        iyy="0.0031058955885761"
        iyz="0.00025449626953172"
        izz="0.0186287374840551" />
    </inertial>
    <visual>
      <origin
        xyz="0 0 0"
        rpy="0 0 0" />
      <geometry>
        <mesh
          filename="package://rightarm/meshes/rightarm_link2.STL" />
      </geometry>
      <material
        name="">
        <color
          rgba="0.752941176470588 0.752941176470588 0.752941176470588 1" />
      </material>
    </visual>
    <collision>
      <origin
        xyz="0 0 0"
        rpy="0 0 0" />
      <geometry>
        <mesh
          filename="package://rightarm/meshes/rightarm_link2.STL" />
      </geometry>
    </collision>
  </link>
  <joint
    name="rightarm_joint2"
    type="revolute">
    <origin
      xyz="0 0 0"
      rpy="1.5708 0 0" />
    <parent
      link="rightarm_link1" />
    <child
      link="rightarm_link2" />
    <axis
      xyz="0 0 1" />
    <limit
      lower="-2.0944"
      upper="2.0944"
      effort="100"
      velocity="5" />
  </joint>
  <link
    name="rightarm_link3">
    <inertial>
      <origin
        xyz="0.0155054054014346 -0.0176104587173533 -0.0972649243526418"
        rpy="0 0 0" />
      <mass
        value="0.209213306011879" />
      <inertia
        ixx="0.00173915719253397"
        ixy="2.27350480852934E-05"
        ixz="-0.000221363794616361"
        iyy="0.0018810977872288"
        iyz="0.00015929064906947"
        izz="0.000333123310451503" />
    </inertial>
    <visual>
      <origin
        xyz="0 0 0"
        rpy="0 0 0" />
      <geometry>
        <mesh
          filename="package://rightarm/meshes/rightarm_link3.STL" />
      </geometry>
      <material
        name="">
        <color
          rgba="0.898039215686275 0.913725490196078 0.925490196078431 1" />
      </material>
    </visual>
    <collision>
      <origin
        xyz="0 0 0"
        rpy="0 0 0" />
      <geometry>
        <mesh
          filename="package://rightarm/meshes/rightarm_link3.STL" />
      </geometry>
    </collision>
  </link>
  <joint
    name="rightarm_joint3"
    type="revolute">
    <origin
      xyz="0 0.4495 0"
      rpy="-1.5708 0 0" />
    <parent
      link="rightarm_link2" />
    <child
      link="rightarm_link3" />
    <axis
      xyz="0 0 1" />
    <limit
      lower="-2.9671"
      upper="2.9671"
      effort="100"
      velocity="5" />
  </joint>
  <link
    name="rightarm_link4">
    <inertial>
      <origin
        xyz="-0.0110265333983113 0.079985203929629 -0.00108071218906545"
        rpy="0 0 0" />
      <mass
        value="1.33690625718003" />
      <inertia
        ixx="0.0167776214945798"
        ixy="0.00198890984901769"
        ixz="-2.96057292568204E-05"
        iyy="0.00218457251751039"
        iyz="0.000118920676489958"
        izz="0.0167428671342609" />
    </inertial>
    <visual>
      <origin
        xyz="0 0 0"
        rpy="0 0 0" />
      <geometry>
        <mesh
          filename="package://rightarm/meshes/rightarm_link4.STL" />
      </geometry>
      <material
        name="">
        <color
          rgba="0.752941176470588 0.752941176470588 0.752941176470588 1" />
      </material>
    </visual>
    <collision>
      <origin
        xyz="0 0 0"
        rpy="0 0 0" />
      <geometry>
        <mesh
          filename="package://rightarm/meshes/rightarm_link4.STL" />
      </geometry>
    </collision>
  </link>
  <joint
    name="rightarm_joint4"
    type="revolute">
    <origin
      xyz="0.03 0 0"
      rpy="1.5708 0 0" />
    <parent
      link="rightarm_link3" />
    <child
      link="rightarm_link4" />
    <axis
      xyz="0 0 1" />
    <limit
      lower="-2.7925"
      upper="2.0944"
      effort="100"
      velocity="5" />
  </joint>
  <link
    name="rightarm_link5">
    <inertial>
      <origin
        xyz="1.0380920345554E-08 -0.0443595329846337 -0.105428960201801"
        rpy="0 0 0" />
      <mass
        value="0.10575077384632" />
      <inertia
        ixx="0.000617136760733647"
        ixy="-3.54168104941269E-11"
        ixz="6.68780403784148E-11"
        iyy="0.000561067761108571"
        iyz="0.000173267808268953"
        izz="0.00015958291466493" />
    </inertial>
    <visual>
      <origin
        xyz="0 0 0"
        rpy="0 0 0" />
      <geometry>
        <mesh
          filename="package://rightarm/meshes/rightarm_link5.STL" />
      </geometry>
      <material
        name="">
        <color
          rgba="0.898039215686275 0.913725490196078 0.925490196078431 1" />
      </material>
    </visual>
    <collision>
      <origin
        xyz="0 0 0"
        rpy="0 0 0" />
      <geometry>
        <mesh
          filename="package://rightarm/meshes/rightarm_link5.STL" />
      </geometry>
    </collision>
  </link>
  <joint
    name="rightarm_joint5"
    type="revolute">
    <origin
      xyz="-0.03 0.4495 0"
      rpy="-1.5708 0 0" />
    <parent
      link="rightarm_link4" />
    <child
      link="rightarm_link5" />
    <axis
      xyz="0 0 1" />
    <limit
      lower="-2.9671"
      upper="2.9671"
      effort="100"
      velocity="5" />
  </joint>
  <link
    name="rightarm_link6">
    <inertial>
      <origin
        xyz="-0.00111786512590739 0.00737759119391557 -0.00255095894124477"
        rpy="0 0 0" />
      <mass
        value="2.16214825847122" />
      <inertia
        ixx="0.00602513474729964"
        ixy="-1.78610000917077E-05"
        ixz="-0.000134785697607459"
        iyy="0.0050933913728733"
        iyz="-5.66252208164908E-05"
        izz="0.00621299091987803" />
    </inertial>
    <visual>
      <origin
        xyz="0 0 0"
        rpy="0 0 0" />
      <geometry>
        <mesh
          filename="package://rightarm/meshes/rightarm_link6.STL" />
      </geometry>
      <material
        name="">
        <color
          rgba="0.792156862745098 0.819607843137255 0.933333333333333 1" />
      </material>
    </visual>
    <collision>
      <origin
        xyz="0 0 0"
        rpy="0 0 0" />
      <geometry>
        <mesh
          filename="package://rightarm/meshes/rightarm_link6.STL" />
      </geometry>
    </collision>
  </link>
  <joint
    name="rightarm_joint6"
    type="revolute">
    <origin
      xyz="0 0 0"
      rpy="1.5708 0 0" />
    <parent
      link="rightarm_link5" />
    <child
      link="rightarm_link6" />
    <axis
      xyz="0 0 1" />
    <limit
      lower="-2.1812"
      upper="2.1812"
      effort="100"
      velocity="5" />
  </joint>
  <link
    name="rightarm_link7">
    <inertial>
      <origin
        xyz="1.11022302462516E-16 -0.000999999999999982 0.134757462209856"
        rpy="0 0 0" />
      <mass
        value="0.376714147207618" />
      <inertia
        ixx="0.00071966666838249"
        ixy="4.02513576305418E-19"
        ixz="1.87319411000545E-19"
        iyy="0.000347343623259773"
        iyz="3.3852533470092E-19"
        izz="0.000643499293433103" />
    </inertial>
    <visual>
      <origin
        xyz="0 0 0"
        rpy="0 0 0" />
      <geometry>
        <mesh
          filename="package://rightarm/meshes/rightarm_link7.STL" />
      </geometry>
      <material
        name="">
        <color
          rgba="0.752941176470588 0.752941176470588 0.752941176470588 1" />
      </material>
    </visual>
    <collision>
      <origin
        xyz="0 0 0"
        rpy="0 0 0" />
      <geometry>
        <mesh
          filename="package://rightarm/meshes/rightarm_link7.STL" />
      </geometry>
    </collision>
  </link>
  <joint
    name="rightarm_joint7"
    type="revolute">
    <origin
      xyz="0 0 0"
      rpy="-1.5708 0 0" />
    <parent
      link="rightarm_link6" />
    <child
      link="rightarm_link7" />
    <axis
      xyz="0 0 1" />
    <limit
      lower="-2.9671"
      upper="2.9671"
      effort="100"
      velocity="5" />
  </joint>
</robot>
